Workbook

Sheet Consultas
A7: =CONCATENATE("Consulta Externa otorgada, ",Control!B4) -> Consulta Externa otorgada, Diciembre 2025
A8: Fuente: SUI 27, Motivos de Demanda de la Consulta Externa
A10: Clave | B10: Nombre OOAD o UMAE | C10: Consulta Externa
C11: Total | D11: Medicina Familiar | E11: Dental | F11: Especialidades | G11: Urgencias
A12: Nacional | C12: =+SUM(C13+C49) -> 157777491 | D12: =+SUM(D13+D49) -> 104610787 | E12: =+SUM(E13+E49) -> 6367372 | F12: =+SUM(F13+F49) -> 29591768 | G12: =+SUM(G13+G49) -> 17207564
A13: Total Delegaciones (Primer y Segundo Nivel) | C13: =+SUM(C14:C48) -> 151870426 | D13: =+SUM(D14:D48) -> 104610787 | E13: =+SUM(E14:E48) -> 6365887 | F13: =+SUM(F14:F48) -> 24388014 | G13: =+SUM(G14:G48) -> 16505738
A14: 01 | B14: Aguascalientes | C14: 2861938 | D14: 1877305 | E14: 107628 | F14: 582125 | G14: 294880
A15: 02 | B15: Baja California | C15: 5877852 | D15: 3856278 | E15: 256148 | F15: 1001692 | G15: 763734
A16: 03 | B16: Baja California Sur | C16: 1552717 | D16: 967354 | E16: 83888 | F16: 346322 | G16: 155153
A17: 04 | B17: Campeche | C17: 1208873 | D17: 788698 | E17: 58813 | F17: 231083 | G17: 130279
A18: 05 | B18: Coahuila | C18: 6273207 | D18: 4081467 | E18: 270973 | F18: 960091 | G18: 960676
A19: 06 | B19: Colima | C19: 1330962 | D19: 809171 | E19: 60312 | F19: 271629 | G19: 189850
A20: 07 | B20: Chiapas | C20: 2262765 | D20: 1606986 | E20: 94641 | F20: 349507 | G20: 211631
A21: 08 | B21: Chihuahua | C21: 5911897 | D21: 3971140 | E21: 178019 | F21: 1080070 | G21: 682668
A22: 10 | B22: Durango | C22: 2753613 | D22: 1863485 | E22: 86211 | F22: 421514 | G22: 382403
A23: 11 | B23: Guanajuato | C23: 6045139 | D23: 4197491 | E23: 310167 | F23: 858175 | G23: 679306
A24: 12 | B24: Guerrero | C24: 2396198 | D24: 1613411 | E24: 95893 | F24: 413916 | G24: 272978
A25: 13 | B25: Hidalgo | C25: 2492969 | D25: 1689874 | E25: 99391 | F25: 490183 | G25: 213521
A26: 14 | B26: Jalisco | C26: 11863621 | D26: 7838839 | E26: 356819 | F26: 2036713 | G26: 1631250
A27: 15 | B27: México Oriente | C27: 10483785 | D27: 7790168 | E27: 513832 | F27: 1388969 | G27: 790816
A28: 16 | B28: México Poniente | C28: 5735166 | D28: 4144404 | E28: 306155 | F28: 830114 | G28: 454493
A29: 17 | B29: Michoacán | C29: 4334633 | D29: 2861066 | E29: 185075 | F29: 825634 | G29: 462858
A30: 18 | B30: Morelos | C30: 2490172 | D30: 1638570 | E30: 88615 | F30: 393284 | G30: 369703
A31: 19 | B31: Nayarit | C31: 1810775 | D31: 1124203 | E31: 64879 | F31: 379900 | G31: 241793
A32: 20 | B32: Nuevo León | C32: 9983855 | D32: 7479758 | E32: 312709 | F32: 1182477 | G32: 1008911
A33: 21 | B33: Oaxaca | C33: 1788028 | D33: 1147136 | E33: 83779 | F33: 345402 | G33: 211711
... A48: 40 | B48: Ciudad de México Sur | C48: 9536492 | D48: 6543433 | E48: 298925 | F48: 1847147 | G48: 846987
A49: Total UMAE | C49: =+SUM(C50:C74) -> 5907065 | D49: =+SUM(D50:D74) -> 0 | E49: =+SUM(E50:E74) -> 1485 | F49: =+SUM(F50:F74) -> 5203754 | G49: =+SUM(G50:G74) -> 701826
A50: 4A | B50: UMAE 01 HES CMN La Raza | C50: 354863 | D50: 0 | E50: 0 | F50: 333285 | G50: 21578
A51: 4B | B51: UMAE 02 HES CMN Siglo XXI | C51: 448202 | D51: 0 | E51: 0 | F51: 426561 | G51: 21641
A52: 4C | B52: UMAE 03 HES CMN Occidente | C52: 356066 | D52: 0 | E52: 0 | F52: 332964 | G52: 23102
A53: 4D | B53: UMAE 04 HES Monterrey | C53: 356646 | D53: 0 | E53: 0 | F53: 323603 | G53: 33043
A54: 4E | B54: UMAE 05 HES Torreón | C54: 250798 | D54: 0 | E54: 0 | F54: 242025 | G54: 8773
A55: 4F | B55: UMAE 06 HES Puebla | C55: 208652 | D55: 0 | E55: 0 | F55: 200012 | G55: 8640
A56: 4G | B56: UMAE 07 HES CMN del Bajío | C56: 215603 | D56: 0 | E56: 0 | F56: 200523 | G56: 15080
A57: 4H | B57: UMAE 08 HES Obregón | C57: 177107 | D57: 0 | E57: 0 | F57: 171361 | G57: 5746
A58: 4I | B58: UMAE 09 HES Veracruz | C58: 239246 | D58: 0 | E58: 0 | F58: 228395 | G58: 10851
A59: 4J | B59: UMAE 10 HES 1 Mérida | C59: 88981 | D59: 0 | E59: 0 | F59: 86387 | G59: 2594
A60: 4K | B60: UMAE 11 HGO CMN La Raza | C60: 194964 | D60: 0 | E60: 0 | F60: 187659 | G60: 7305
A61: 4L | B61: UMAE 12 HGO San Angel | C61: 183710 | D61: 0 | E61: 0 | F61: 161198 | G61: 22512
...

Sheet Egresos
A7: =CONCATENATE("Atenciones Hospitalarias, ",Control!B4) -> Atenciones Hospitalarias, Diciembre 2025
A8: Fuente: SUI 13, Egresos Hospitalarios. | J8: Fuente: BDUCI | L8: Fuente: SIMO IQx | O8: Fuente: Nacidos Vivos, EGRNAC; Partos, Cesáreas y Abortos, EGRTOCO.
A10: Clave | B10: Nombre OOAD o UMAE | C10: Atenciones Hospitalarias | J10: Atenciones Hospitalarias | L10: Atenciones Hospitalarias | O10: Atenciones Hospitalarias
C11: Egresos Hospitalarios | E11: Atenciones Hospitalarias UMAA | F11: Días Paciente | G11: Mortalidad Hospitalaria | H11: Egresos Observación Urgencias | J11: Egresos UCI | L11: Intervenciones Quirúrgicas | M11: Intervenciones Quirúrgicas Principales | O11: Partos | P11: Nacidos Vivos | Q11: Abortos | R11: Cesáreas | S11: Mortinatos
C12: Camas Censables | D12: Camas no Censables | E12: Camas no Censables
A13: Nacional | C13: =C14+C50 -> 2352839 | D13: =D14+D50 -> 426880 | E13: =E14+E50 -> 124832 | F13: =F14+F50 -> 10858467 | G13: =G14+G50 -> 96979 | H13: =H14+H50 -> 3455697 | J13: =J50+J14 -> 58080 | L13: =L14+L50 -> 2211122 | M13: =M14+M50 -> 1709903 | O13: =SUM(O14+O50) -> 271231 | P13: =SUM(P14+P50) -> 271955 | Q13: =SUM(Q14+Q50) -> 34580 | R13: =SUM(R14+R50) -> 143052 | S13: =SUM(S14+S50) -> 2538
A14: Total Delegaciones (Primer y Segundo Nivel) | C14: =SUM(C15:C49) -> 1952266 | D14: =SUM(D15:D49) -> 340667 | E14: =SUM(E15:E49) -> 124832 | F14: =SUM(F15:F49) -> 8598481 | G14: =SUM(G15:G49) -> 84883 | H14: =SUM(H15:H49) -> 3170592 | J14: =SUM(J15:J49) -> 29189 | L14: =SUM(L15:L49) -> 1703367 | M14: =SUM(M15:M49) -> 1368711 | O14: =SUM(O15:O49) -> 238723 | P14: =SUM(P15:P49) -> 238958 | Q14: =SUM(Q15:Q49) -> 31441 | R14: =SUM(R15:R49) -> 123648 | S14: =SUM(S15:S49) -> 2028
A15: 01 | B15: Aguascalientes | C15: 36864 | D15: 3300 | E15: 4959 | F15: 166524 | G15: 1359 | H15: 54767 | J15: 802 | L15: 41473 | M15: 26753 | O15: 4444 | P15: 4442 | Q15: 777 | R15: 1909 | S15: 42
A16: 02 | B16: Baja California | C16: 84159 | D16: 14476 | E16: 3692 | F16: 392350 | G16: 3450 | H16: 106909 | J16: 1429 | L16: 74225 | M16: 59588 | O16: 13514 | P16: 13544 | Q16: 2077 | R16: 6064 | S16: 117
A17: 03 | B17: Baja California Sur | C17: 26420 | D17: 2585 | E17: 2490 | F17: 107539 | G17: 725 | H17: 36345 | J17: 380 | L17: 22587 | M17: 17604 | O17: 3755 | P17: 3765 | Q17: 807 | R17: 2232 | S17: 25
A18: 04 | B18: Campeche | C18: 13560 | D18: 1979 | E18: 3272 | F18: 58520 | G18: 438 | H18: 21395 | J18: 137 | L18: 15125 | M18: 11758 | O18: 1805 | P18: 1806 | Q18: 292 | R18: 1108 | S18: 15
A19: 05 | B19: Coahuila | C19: 102463 | D19: 15537 | E19: 13419 | F19: 367495 | G19: 4441 | H19: 182067 | J19: 999 | L19: 79359 | M19: 70300 | O19: 12645 | P19: 12669 | Q19: 1651 | R19: 5768 | S19: 149
A20: 06 | B20: Colima | C20: 20424 | D20: 2906 | E20: 0 | F20: 83440 | G20: 779 | H20: 38708 | J20: 490 | L20: 16809 | M20: 11963 | O20: 2407 | P20: 2419 | Q20: 123 | R20: 1223 | S20: 17
A21: 07 | B21: Chiapas | C21: 27511 | D21: 1766 | E21: 3254 | F21: 124724 | G21: 957 | H21: 33892 | J21: 396 | L21: 25329 | M21: 18588 | O21: 3881 | P21: 3917 | Q21: 156 | R21: 2509 | S21: 30
A22: 08 | B22: Chihuahua | C22: 95371 | D22: 11266 | E22: 4534 | F22: 423472 | G22: 4232 | H22: 133749 | J22: 1688 | L22: 68589 | M22: 56718 | O22: 12437 | P22: 12462 | Q22: 1955 | R22: 6015 | S22: 99
A23: 10 | B23: Durango | C23: 40736 | D23: 4118 | E23: 4771 | F23: 154376 | G23: 1384 | H23: 52540 | J23: 235 | L23: 33123 | M23: 30105 | O23: 5505 | P23: 5520 | Q23: 496 | R23: 2568 | S23: 42
A24: 11 | B24: Guanajuato | C24: 70087 | D24: 13229 | E24: 5151 | F24: 312608 | G24: 2631 | H24: 126937 | J24: 813 | L24: 62184 | M24: 51156 | O24: 8369 | P24: 8362 | Q24: 1440 | R24: 4467 | S24: 60
A25: 12 | B25: Guerrero | C25: 28642 | D25: 10879 | E25: 8159 | F25: 114687 | G25: 926 | H25: 50253 | J25: 447 | L25: 38251 | M25: 34001 | O25: 3987 | P25: 3989 | Q25: 422 | R25: 2317 | S25: 21
A26: 13 | B26: Hidalgo | C26: 33066 | D26: 5971 | E26: 0 | F26: 147605 | G26: 1490 | H26: 55012 | J26: 597 | L26: 28972 | M26: 21179 | O26: 3714 | P26: 3722 | Q26: 232 | R26: 2249 | S26: 26
... A49: 40 | B49: Ciudad de México Sur | C49: 90449 | D49: 15376 | E49: 6994 | F49: 533301 | G49: 5337 | H49: 163958 | J49: 1802 | L49: 89687 | M49: 72567 | O49: 3997 | P49: 3973 | Q49: 790 | R49: 1653 | S49: 31
A50: Total UMAE | C50: =SUM(C51:C75) -> 400573 | D50: =SUM(D51:D75) -> 86213 | E50: =SUM(E51:E75) -> 0 | F50: =SUM(F51:F75) -> 2259986 | G50: =SUM(G51:G75) -> 12096 | H50: =SUM(H51:H75) -> 285105 | J50: =SUM(J51:J75) -> 28891 | L50: =SUM(L51:L75) -> 507755 | M50: =SUM(M51:M75) -> 341192 | O50: =SUM(O51:O75) -> 32508 | P50: =SUM(P51:P75) -> 32997 | Q50: =SUM(Q51:Q75) -> 3139 | R50: =SUM(R51:R75) -> 19404 | S50: =SUM(S51:S75) -> 510
A51: 4A | B51: UMAE 01 HES CMN La Raza | C51: 22701 | D51: 0 | E51: 0 | F51: 157941 | G51: 1331 | H51: 20984 | J51: 1930 | L51: 11841 | M51: 9687
A52: 4B | B52: UMAE 02 HES CMN Siglo XXI | C52: 22497 | D52: 6218 | E52: 0 | F52: 107089 | G52: 708 | H52: 18094 | J52: 811 | L52: 34203 | M52: 20484
A53: 4C | B53: UMAE 03 HES CMN Occidente | C53: 18866 | D53: 6801 | E53: 0 | F53: 151073 | G53: 1290 | H53: 15151 | J53: 2869 | L53: 35162 | M53: 20007
A54: 4D | B54: UMAE 04 HES Monterrey | C54: 17291 | D54: 7161 | E54: 0 | F54: 111879 | G54: 932 | H54: 26129 | J54: 1281 | L54: 17573 | M54: 13433
A55: 4E | B55: UMAE 05 HES Torreón | C55: 16228 | D55: 3989 | E55: 0 | F55: 84435 | G55: 700 | H55: 8364 | J55: 2034 | L55: 19351 | M55: 15392
A56: 4F | B56: UMAE 06 HES Puebla | C56: 17957 | D56: 2022 | E56: 0 | F56: 89305 | G56: 776 | H56: 8645 | J56: 1573 | L56: 10184 | M56: 8306
A57: 4G | B57: UMAE 07 HES CMN del Bajío | C57: 11018 | D57: 5384 | E57: 0 | F57: 55948 | G57: 621 | H57: 9818 | J57: 1505 | L57: 16279 | M57: 11975
A58: 4H | B58: UMAE 08 HES Obregón | C58: 8496 | D58: 7417 | E58: 0 | F58: 60401 | G58: 338 | H58: 5719 | J58: 1244 | L58: 23563 | M58: 14233
A59: 4I | B59: UMAE 09 HES Veracruz | C59: 15243 | D59: 2886 | E59: 0 | F59: 106042 | G59: 795 | H59: 12497 | J59: 1345 | L59: 16282 | M59: 11507
A60: 4J | B60: UMAE 10 HES 1 Mérida | C60: 8275 | D60: 62 | E60: 0 | F60: 49569 | G60: 291 | H60: 1993 | J60: 434 | L60: 4128 | M60: 3284 | O60: 68 | P60: 73 | Q60: 1 | R60: 68 | S60: 0
A61: 4K | B61: UMAE 11 HGO CMN La Raza | C61: 19655 | D61: 1275 | E61: 0 | F61: 83474 | G61: 234 | H61: 6000 | J61: 571 | L61: 17415 | M61: 11195 | O61: 5122 | P61: 5350 | Q61: 131 | R61: 3590 | S61: 112
A62: 4L | B62: UMAE 12 HGO San Angel | C62: 29756 | D62: 4105 | E62: 0 | F62: 113862 | G62: 97 | H62: 10414 | J62: 372 | L62: 22279 | M62: 16488 | O62: 8510 | P62: 8548 | Q62: 364 | R62: 5032 | S62: 112
A63: 4M | B63: UMAE 13 HGO CMN Occidente | C63: 16104 | D63: 625 | E63: 0 | F63: 60436 | G63: 202 | H63: 2436 | J63: 335 | L63: 16336 | M63: 10018 | O63: 3941 | P63: 4082 | Q63: 293 | R63: 2917 | S63: 96
A64: 4N | B64: UMAE 14 HGO Monterrey | C64: 31394 | D64: 837 | E64: 0 | F64: 101189 | G64: 106 | H64: 4656 | J64: 154 | L64: 23139 | M64: 13879 | O64: 9597 | P64: 9634 | Q64: 1511 | R64: 5218 | S64: 138
A65: 4O | B65: UMAE 15 HTO Magdalena Salinas | C65: 25931 | D65: 1832 | E65: 0 | F65: 171332 | G65: 354 | H65: 25772 | J65: 808 | L65: 46308 | M65: 36084
A66: 4P | B66: UMAE 16 HTO Lomas Verdes | C66: 16282 | D66: 780 | E66: 0 | F66: 92397 | G66: 192 | H66: 13968 | J66: 365 | L66: 20377 | M66: 17725
A67: 4Q | B67: UMAE 17 HTO Puebla | C67: 7853 | D67: 654 | E67: 0 | F67: 37409 | G67: 138 | H67: 6689 | J67: 212 | L67: 14473 | M67: 9269
A68: 4R | B68: UMAE 18 HTO Monterrey | C68: 12705 | D68: 9568 | E68: 0 | F68: 110161 | G68: 235 | H68: 9719 | J68: 537 | L68: 27855 | M68: 24428
A69: 4S | B69: UMAE 19 HP CMN Siglo XXI | C69: 5424 | D69: 1385 | E69: 0 | F69: 51123 | G69: 220 | H69: 5702 | J69: 694 | L69: 9942 | M69: 4860
...

Sheet  Aux Dx
A7: =CONCATENATE("Auxiliares de Diagnóstico, ",Control!B4) -> Auxiliares de Diagnóstico, Diciembre 2025
A8: Fuente: DataMart Estadísticas Médicas (Se presentan las cifras al cierre de mayo 2022 debido a la falla general que se presentó dicha plataforma)
A10: Clave | B10: Nombre OOAD o UMAE | C10: Auxiliares de Diagnóstico (estudios o Sesiones)
C11: AUDIOMETRIA | D11: CITOLOGIA EXFOLIATIVA | E11: ECO CARDIOGRAMAS | F11: ECO SONOGRAFIA | G11: ELECTRO CARDIOGRAFIA | H11: ELECTRO ENCEFALOGRAFIA | I11: ELECTRO MIOGRAFIA | J11: ENDOSCOPIAS GASTRICAS | K11: ENDOSCOPIAS GINECOLOGICAS | L11: ENDOSCOPIAS NEUMOLOGICAS | M11: ENDOSCOPIAS UROLOGICAS | N11: ESPIROMETRIAS | O11: FISIOLOGIA CARDIOPULMONAR | P11: FLURO ANGIOGRAFIA | Q11: FONIATRIA | R11: FONO CARDIOGRAFIA | S11: HEMO DINAMICA | T11: HISTO PATOLOGIA | U11: HOOLTER | V11: LABORATORIO CLINICO | W11: MEDICINA NUCLEAR | X11: POTENCIALES EVOCADOS | Y11: PRUEBA DE ESFUERZO | Z11: PRUEBAS VESTIBULARES | AA11: PSICOLOGIA | AB11: RADIODIAGNOSTICO | AC11: RESONANCIA MAGNETICA | AD11: TAMIZAJE DEL 1ER. TRIMESTRE | AE11: TOMOGRAFIA AXIAL COMPUTARIZADA | AF11: ULTRASONIDO OBSTETRICO DE SEGUNDO NIVEL | AG11: VECTO CARDIOGRAFIA
A12: Nacional | C12: =+SUM(C13,C49) -> 150336 | D12: =+SUM(D13,D49) -> 1924135 | E12: =+SUM(E13,E49) -> 240391 | F12: =+SUM(F13,F49) -> 3649066 | G12: =+SUM(G13,G49) -> 3106345 | H12: =+SUM(H13,H49) -> 95458 | I12: =+SUM(I13,I49) -> 109542 | J12: =+SUM(J13,J49) -> 198055 | ... AG12: =+SUM(AG13,AG49) -> 12638
A13: Total Delegaciones (Primer y Segundo Nivel) | C13: =+SUM(C14:C48) -> 97335 | D13: =+SUM(D14:D48) -> 1839248 | E13: =+SUM(E14:E48) -> 106422 | F13: =+SUM(F14:F48) -> 3014845 | G13: =+SUM(G14:G48) -> 2766415 | H13: =+SUM(H14:H48) -> 75818 | I13: =+SUM(I14:I48) -> 82561 | J13: =+SUM(J14:J48) -> 170585 | ... AG13: =+SUM(AG14:AG48) -> 12638
A14: 1 | B14: Aguascalientes | C14: 1728 | D14: 27427 | E14: 5538 | F14: 77468 | G14: 80844 | H14: 1322 | I14: 2680 | J14: 2539 | K14: 0 | L14: 0 | M14: 100 | N14: 3997 | O14: 0 | P14: 0 | Q14: 0 | R14: 0 | S14: 744 | T14: 31234 | U14: 2522 | V14: 3776407 | W14: 0 | X14: 707 | Y14: 993 | Z14: 1226 | AA14: 3189 | AB14: 541943 | AC14: 0 | AD14: 1336 | AE14: 45614 | AF14: 6633 | AG14: 0
A15: 2 | B15: Baja California | C15: 3954 | D15: 61974 | E15: 5045 | F15: 105282 | G15: 76555 | H15: 4261 | I15: 3224 | J15: 1034 | K15: 87 | L15: 0 | M15: 0 | N15: 3772 | O15: 0 | P15: 0 | Q15: 72 | R15: 0 | S15: 2446 | T15: 31178 | U15: 1097 | V15: 11517969 | W15: 0 | X15: 579 | Y15: 681 | Z15: 593 | AA15: 3800 | AB15: 622914 | AC15: 0 | AD15: 163 | AE15: 39183 | AF15: 22362 | AG15: 0
A16: 3 | B16: Baja California Sur | C16: 0 | D16: 12993 | E16: 1217 | F16: 41075 | G16: 48040 | H16: 2276 | I16: 273 | J16: 1340 | K16: 0 | L16: 17 | M16: 1 | N16: 465 | O16: 0 | P16: 1477 | Q16: 0 | R16: 0 | S16: 455 | T16: 8788 | U16: 716 | V16: 3312889 | W16: 0 | X16: 2 | Y16: 242 | Z16: 0 | AA16: 2648 | AB16: 237253 | AC16: 0 | AD16: 62 | AE16: 23221 | AF16: 3445 | AG16: 0
A17: 4 | B17: Campeche | C17: 0 | D17: 999 | E17: 163 | F17: 25167 | G17: 20595 | H17: 0 | I17: 264 | J17: 511 | K17: 0 | L17: 0 | M17: 0 | N17: 765 | O17: 0 | P17: 0 | Q17: 0 | R17: 0 | S17: 195 | T17: 3501 | U17: 0 | V17: 1651399 | W17: 0 | X17: 0 | Y17: 0 | Z17: 0 | AA17: 952 | AB17: 121714 | AC17: 0 | AD17: 0 | AE17: 10261 | AF17: 1356 | AG17: 0
A18: 5 | B18: Coahuila | C18: 2263 | D18: 64302 | E18: 2485 | F18: 87208 | G18: 172685 | H18: 939 | I18: 6734 | J18: 1465 | K18: 86 | L18: 22 | M18: 82 | N18: 2194 | O18: 0 | P18: 0 | Q18: 0 | R18: 0 | S18: 496 | T18: 26912 | U18: 100 | V18: 12507679 | W18: 0 | X18: 168 | Y18: 118 | Z18: 526 | AA18: 4363 | AB18: 835237 | AC18: 0 | AD18: 0 | AE18: 61196 | AF18: 1304 | AG18: 0
A19: 6 | B19: Colima | C19: 118 | D19: 2045 | E19: 0 | F19: 23691 | G19: 26296 | H19: 726 | I19: 742 | J19: 1200 | K19: 0 | L19: 0 | M19: 0 | N19: 1510 | O19: 0 | P19: 0 | Q19: 819 | R19: 0 | S19: 145 | T19: 15346 | U19: 0 | V19: 2717828 | W19: 0 | X19: 61 | Y19: 0 | Z19: 0 | AA19: 1871 | AB19: 158485 | AC19: 0 | AD19: 0 | AE19: 15316 | AF19: 0 | AG19: 0
A20: 7 | B20: Chiapas | C20: 0 | D20: 10409 | E20: 5393 | F20: 60997 | G20: 24834 | H20: 1747 | I20: 1281 | J20: 690 | K20: 0 | L20: 0 | M20: 14 | N20: 431 | O20: 0 | P20: 0 | Q20: 0 | R20: 0 | S20: 4 | T20: 13037 | U20: 463 | V20: 4814193 | W20: 0 | X20: 0 | Y20: 43 | Z20: 0 | AA20: 5290 | AB20: 321098 | AC20: 0 | AD20: 0 | AE20: 36255 | AF20: 0 | AG20: 0
A21: 8 | B21: Chihuahua | C21: 1073 | D21: 15430 | E21: 3944 | F21: 118788 | G21: 91270 | H21: 2447 | I21: 3696 | J21: 1646 | K21: 0 | L21: 0 | M21: 71 | N21: 1769 | O21: 0 | P21: 0 | Q21: 0 | R21: 0 | S21: 209 | T21: 20987 | U21: 281 | V21: 14227125 | W21: 0 | X21: 0 | Y21: 898 | Z21: 237 | AA21: 13726 | AB21: 636911 | AC21: 0 | AD21: 2049 | AE21: 102964 | AF21: 4163 | AG21: 12638
A22: 10 | B22: Durango | C22: 0 | D22: 12963 | E22: 3918 | F22: 38471 | G22: 69027 | H22: 0 | I22: 646 | J22: 2136 | K22: 0 | L22: 0 | M22: 0 | N22: 771 | O22: 0 | P22: 0 | Q22: 0 | R22: 0 | S22: 92 | T22: 3230 | U22: 0 | V22: 4714186 | W22: 0 | X22: 6 | Y22: 294 | Z22: 0 | AA22: 2854 | AB22: 310597 | AC22: 0 | AD22: 0 | AE22: 19897 | AF22: 0 | AG22: 0
A23: 11 | B23: Guanajuato | C23: 1980 | D23: 30596 | E23: 3346 | F23: 87824 | G23: 80018 | H23: 2230 | I23: 2808 | J23: 80575 | K23: 0 | L23: 0 | M23: 0 | N23: 4356 | O23: 0 | P23: 6669 | Q23: 417 | R23: 0 | S23: 0 | T23: 65636 | U23: 1577 | V23: 9462564 | W23: 0 | X23: 365 | Y23: 2 | Z23: 1648 | AA23: 1515 | AB23: 610904 | AC23: 0 | AD23: 434 | AE23: 41461 | AF23: 1720 | AG23: 0
A24: 12 | B24: Guerrero | C24: 0 | D24: 24364 | E24: 0 | F24: 52314 | G24: 37666 | H24: 644 | I24: 606 | J24: 1657 | K24: 0 | L24: 0 | M24: 0 | N24: 0 | O24: 0 | P24: 0 | Q24: 0 | R24: 0 | S24: 10 | T24: 9733 | U24: 0 | V24: 4231677 | W24: 0 | X24: 0 | Y24: 0 | Z24: 0 | AA24: 4171 | AB24: 264723 | AC24: 0 | AD24: 0 | AE24: 10725 | AF24: 0 | AG24: 0
A25: 13 | B25: Hidalgo | C25: 7 | D25: 51756 | E25: 4565 | F25: 98436 | G25: 61984 | H25: 1345 | I25: 2552 | J25: 2154 | K25: 0 | L25: 0 | M25: 18 | N25: 0 | O25: 0 | P25: 0 | Q25: 424 | R25: 0 | S25: 209 | T25: 15212 | U25: 1026 | V25: 3854704 | W25: 0 | X25: 0 | Y25: 632 | Z25: 984 | AA25: 5544 | AB25: 360368 | AC25: 0 | AD25: 1858 | AE25: 16485 | AF25: 10157 | AG25: 0
... A48: 40 | B48: Ciudad de México Sur | C48: 3536 | D48: 74623 | E48: 2514 | F48: 173019 | G48: 198559 | H48: 6582 | I48: 7717 | J48: 15062 | K48: 0 | L48: 2 | M48: 1891 | N48: 5091 | O48: 0 | P48: 1782 | Q48: 0 | R48: 0 | S48: 0 | T48: 66478 | U48: 583 | V48: 17925114 | W48: 0 | X48: 2460 | Y48: 578 | Z48: 0 | AA48: 47084 | AB48: 1614609 | AC48: 0 | AD48: 1082 | AE48: 118373 | AF48: 7282 | AG48: 0
A49: Total UMAE | C49: =+SUM(C50:C74) -> 53001 | D49: =+SUM(D50:D74) -> 84887 | E49: =+SUM(E50:E74) -> 133969 | F49: =+SUM(F50:F74) -> 634221 | G49: =+SUM(G50:G74) -> 339930 | H49: =+SUM(H50:H74) -> 19640 | I49: =+SUM(I50:I74) -> 26981 | J49: =+SUM(J50:J74) -> 27470 | ... AG49: =+SUM(AG50:AG74) -> 0
A50: 4A | B50: UMAE 1 CMN LA RAZA | C50: 0 | D50: 1582 | E50: 13395 | F50: 12086 | G50: 25863 | H50: 1184 | I50: 0 | J50: 2968 | K50: 0 | L50: 67 | M50: 0 | N50: 768 | O50: 0 | P50: 0 | Q50: 0 | R50: 0 | S50: 4066 | T50: 21888 | U50: 2367 | V50: 3077666 | W50: 229935 | X50: 0 | Y50: 2297 | Z50: 0 | AA50: 18208 | AB50: 43220 | AC50: 0 | AD50: 0 | AE50: 32622 | AF50: 0 | AG50: 0
A51: 4B | B51: UMAE 2 CMN S XXI | C51: 6587 | D51: 969 | E51: 3894 | F51: 140662 | G51: 11054 | H51: 1665 | I51: 3921 | J51: 1402 | K51: 0 | L51: 119 | M51: 1124 | N51: 973 | O51: 0 | P51: 0 | Q51: 0 | R51: 0 | S51: 69724 | T51: 10394 | U51: 690 | V51: 2902944 | W51: 22465 | X51: 296 | Y51: 14 | Z51: 2575 | AA51: 930 | AB51: 165947 | AC51: 0 | AD51: 0 | AE51: 168637 | AF51: 0 | AG51: 0
A52: 4C | B52: UMAE 3 CMN OCC | C52: 9215 | D52: 2668 | E52: 12281 | F52: 13298 | G52: 32400 | H52: 570 | I52: 794 | J52: 1879 | K52: 0 | L52: 859 | M52: 762 | N52: 10563 | O52: 10620 | P52: 0 | Q52: 2663 | R52: 0 | S52: 5895 | T52: 14672 | U52: 552 | V52: 1920313 | W52: 3869 | X52: 266 | Y52: 177 | Z52: 2007 | AA52: 2498 | AB52: 40955 | AC52: 0 | AD52: 0 | AE52: 30884 | AF52: 0 | AG52: 0
A53: 4D | B53: UMAE 4 CMN MTY | C53: 0 | D53: 14680 | E53: 0 | F53: 18576 | G53: 6704 | H53: 2096 | I53: 0 | J53: 2521 | K53: 0 | L53: 0 | M53: 0 | N53: 0 | O53: 0 | P53: 0 | Q53: 0 | R53: 0 | S53: 277 | T53: 10840 | U53: 0 | V53: 1751977 | W53: 8671 | X53: 141 | Y53: 0 | Z53: 0 | AA53: 2006 | AB53: 32437 | AC53: 0 | AD53: 0 | AE53: 52824 | AF53: 0 | AG53: 0
A54: 4E | B54: UMAE 5 TORREON | C54: 0 | D54: 5480 | E54: 3336 | F54: 29955 | G54: 8866 | H54: 977 | I54: 219 | J54: 3913 | K54: 0 | L54: 154 | M54: 467 | N54: 1079 | O54: 0 | P54: 0 | Q54: 0 | R54: 0 | S54: 2461 | T54: 26814 | U54: 1633 | V54: 1596301 | W54: 3705 | X54: 269 | Y54: 463 | Z54: 0 | AA54: 6969 | AB54: 56837 | AC54: 0 | AD54: 0 | AE54: 25188 | AF54: 0 | AG54: 0
A55: 4F | B55: UMAE 6 CMN PUEBLA | C55: 9267 | D55: 2208 | E55: 3757 | F55: 40071 | G55: 10525 | H55: 917 | I55: 1180 | J55: 3793 | K55: 0 | L55: 0 | M55: 999 | N55: 1560 | O55: 5616 | P55: 0 | Q55: 1159 | R55: 0 | S55: 15106 | T55: 13632 | U55: 1089 | V55: 1948907 | W55: 5167 | X55: 191 | Y55: 1252 | Z55: 16716 | AA55: 2965 | AB55: 90976 | AC55: 0 | AD55: 0 | AE55: 32578 | AF55: 0 | AG55: 0
A56: 4G | B56: UMAE 7 CMN BAJIO | C56: 2154 | D56: 2674 | E56: 4614 | F56: 5197 | G56: 11280 | H56: 421 | I56: 1625 | J56: 1760 | K56: 0 | L56: 324 | M56: 79 | N56: 3160 | O56: 0 | P56: 634 | Q56: 862 | R56: 0 | S56: 3312 | T56: 11341 | U56: 1111 | V56: 1978721 | W56: 4087 | X56: 661 | Y56: 1052 | Z56: 958 | AA56: 218 | AB56: 30599 | AC56: 0 | AD56: 0 | AE56: 14920 | AF56: 0 | AG56: 0
A57: 4H | B57: UMAE 8 CMN OBREGON | C57: 977 | D57: 0 | E57: 5073 | F57: 5391 | G57: 13663 | H57: 868 | I57: 395 | J57: 2791 | K57: 0 | L57: 395 | M57: 0 | N57: 1643 | O57: 0 | P57: 0 | Q57: 0 | R57: 0 | S57: 2027 | T57: 0 | U57: 737 | V57: 1032488 | W57: 11075 | X57: 0 | Y57: 68 | Z57: 0 | AA57: 0 | AB57: 47114 | AC57: 0 | AD57: 0 | AE57: 11961 | AF57: 0 | AG57: 0
A58: 4I | B58: UMAE 9 CMN VERACRUZ | C58: 3157 | D58: 19 | E58: 4189 | F58: 16933 | G58: 10132 | H58: 1127 | I58: 937 | J58: 1090 | K58: 0 | L58: 0 | M58: 3126 | N58: 1522 | O58: 1522 | P58: 0 | Q58: 0 | R58: 0 | S58: 5229 | T58: 6011 | U58: 1938 | V58: 1337247 | W58: 0 | X58: 26 | Y58: 1365 | Z58: 673 | AA58: 0 | AB58: 57363 | AC58: 0 | AD58: 0 | AE58: 36078 | AF58: 0 | AG58: 0
A59: 4J | B59: UMAE 10 CMN MERIDA | C59: 0 | D59: 0 | E59: 563 | F59: 8129 | G59: 2262 | H59: 0 | I59: 0 | J59: 0 | K59: 0 | L59: 0 | M59: 0 | N59: 0 | O59: 0 | P59: 0 | Q59: 0 | R59: 0 | S59: 1778 | T59: 388 | U59: 0 | V59: 348278 | W59: 12805 | X59: 0 | Y59: 0 | Z59: 0 | AA59: 0 | AB59: 24603 | AC59: 0 | AD59: 0 | AE59: 20173 | AF59: 0 | AG59: 0
A60: 4K | B60: UMAE 11 CMN LA RAZA | C60: 0 | D60: 4909 | E60: 727 | F60: 20644 | G60: 4843 | H60: 0 | I60: 0 | J60: 0 | K60: 0 | L60: 0 | M60: 0 | N60: 0 | O60: 0 | P60: 0 | Q60: 0 | R60: 0 | S60: 0 | T60: 155617 | U60: 0 | V60: 706832 | W60: 0 | X60: 0 | Y60: 0 | Z60: 0 | AA60: 1590 | AB60: 53106 | AC60: 0 | AD60: 2584 | AE60: 0 | AF60: 15859 | AG60: 0
A61: 4L | B61: UMAE 12 SAN ANGEL | C61: 0 | D61: 4182 | E61: 0 | F61: 15730 | G61: 4460 | H61: 0 | I61: 0 | J61: 0 | K61: 0 | L61: 0 | M61: 0 | N61: 0 | O61: 0 | P61: 0 | Q61: 0 | R61: 0 | S61: 0 | T61: 13529 | U61: 0 | V61: 780956 | W61: 0 | X61: 0 | Y61: 0 | Z61: 0 | AA61: 409 | AB61: 25140 | AC61: 0 | AD61: 1330 | AE61: 0 | AF61: 61849 | AG61: 0
... A74: 4Y | B74: UMAE 25 CMN SIGLO XXI | C74: 0 | D74: 13049 | E74: 0 | F74: 20531 | G74: 8040 | H74: 0 | I74: 0 | J74: 1989 | K74: 404 | L74: 688 | M74: 1920 | N74: 201 | O74: 0 | P74: 0 | Q74: 1605 | R74: 0 | S74: 0 | T74: 147953 | U74: 0 | V74: 1374558 | W74: 23511 | X74: 0 | Y74: 0 | Z74: 0 | AA74: 3862 | AB74: 30698 | AC74: 0 | AD74: 0 | AE74: 31479 | AF74: 0 | AG74: 0

Sheet Aux Tx
A7: =CONCATENATE("Auxiliares de Tratamiento, ",Control!B4) -> Auxiliares de Tratamiento, Diciembre 2025
A8: Fuente: DataMart Estadísticas Médicas (Se presentan las cifras al cierre de mayo 2022 debido a la falla general que se presentó dicha plataforma)
A10: Clave | B10: Nombre OOAD o UMAE | C10: Auxiliares de Tratamiento (estudios o Sesiones)
C11: AMI EN PRELABOR | D11: DIALISIS | E11: FISIOTERAPIA | F11: HEMODIALISIS | G11: INHALOTERAPIA | H11: LITOTRIPSIAS | I11: ORTOPTICA | J11: QUIMIOTERAPIA | K11: RADIOTERAPIA | L11: REEDUCACION OCUPACIONAL | M11: TERAPIA DE LENGUAJE | N11: TERAPIA LASER | O11: TERAPIA OCUPACIONAL | P11: TERAPIA PSICOLOGICA | Q11: TERAPIA RECREATIVA | R11: TERAPIA RESPIRATORIA
A12: Nacional | C12: =SUM(C13+C49) -> 42198 | D12: =SUM(D13+D49) -> 22368156 | E12: =SUM(E13+E49) -> 7705889 | F12: =SUM(F13+F49) -> 2088174 | G12: =SUM(G13+G49) -> 6589503 | H12: =SUM(H13+H49) -> 0 | I12: =SUM(I13+I49) -> 10498 | J12: =SUM(J13+J49) -> 1233290 | ... R12: =SUM(R13+R49) -> 918232
A13: Total Delegaciones (Primer y Segundo Nivel) | C13: =SUM(C14:C48) -> 29839 | D13: =SUM(D14:D48) -> 22303781 | E13: =SUM(E14:E48) -> 6495335 | F13: =SUM(F14:F48) -> 1993322 | G13: =SUM(G14:G48) -> 5606911 | H13: =SUM(H14:H48) -> 0 | I13: =SUM(I14:I48) -> 10498 | J13: =SUM(J14:J48) -> 767251 | ... R13: =SUM(R14:R48) -> 771404
A14: 01 | B14: Aguascalientes | C14: 1128 | D14: 44310 | E14: 79434 | F14: 54082 | G14: 116384 | H14: 0 | I14: 0 | J14: 18201 | K14: 0 | L14: 0 | M14: 3627 | N14: 126 | O14: 7796 | P14: 0 | Q14: 0 | R14: 1699
A15: 02 | B15: Baja California | C15: 457 | D15: 221181 | E15: 140523 | F15: 69895 | G15: 122172 | H15: 0 | I15: 0 | J15: 55371 | K15: 21709 | L15: 317 | M15: 0 | N15: 488 | O15: 20430 | P15: 4077 | Q15: 0 | R15: 0
A16: 03 | B16: Baja California Sur | C16: 2619 | D16: 360845 | E16: 42709 | F16: 48756 | G16: 2841 | H16: 0 | I16: 0 | J16: 6283 | K16: 0 | L16: 0 | M16: 0 | N16: 516 | O16: 0 | P16: 2397 | Q16: 0 | R16: 2619
A17: 04 | B17: Campeche | C17: 0 | D17: 383644 | E17: 27700 | F17: 19705 | G17: 1053 | H17: 0 | I17: 0 | J17: 1807 | K17: 0 | L17: 0 | M17: 0 | N17: 700 | O17: 8653 | P17: 0 | Q17: 0 | R17: 2762
A18: 05 | B18: Coahuila | C18: 0 | D18: 1240544 | E18: 212395 | F18: 82173 | G18: 1146 | H18: 0 | I18: 0 | J18: 16604 | K18: 0 | L18: 0 | M18: 0 | N18: 1313 | O18: 14346 | P18: 2342 | Q18: 0 | R18: 1663
A19: 06 | B19: Colima | C19: 0 | D19: 347445 | E19: 148215 | F19: 23789 | G19: 137105 | H19: 0 | I19: 0 | J19: 7081 | K19: 0 | L19: 206 | M19: 3334 | N19: 0 | O19: 4975 | P19: 2714 | Q19: 0 | R19: 156799
A20: 07 | B20: Chiapas | C20: 0 | D20: 766989 | E20: 97235 | F20: 51109 | G20: 48289 | H20: 0 | I20: 0 | J20: 39042 | K20: 0 | L20: 0 | M20: 116 | N20: 32 | O20: 28658 | P20: 0 | Q20: 0 | R20: 299
A21: 08 | B21: Chihuahua | C21: 1650 | D21: 167734 | E21: 331364 | F21: 71245 | G21: 37760 | H21: 0 | I21: 0 | J21: 35945 | K21: 3502 | L21: 3428 | M21: 17136 | N21: 0 | O21: 24896 | P21: 11846 | Q21: 16870 | R21: 16595
A22: 10 | B22: Durango | C22: 0 | D22: 26008 | E22: 146600 | F22: 48204 | G22: 33840 | H22: 0 | I22: 0 | J22: 17755 | K22: 5609 | L22: 0 | M22: 0 | N22: 88 | O22: 10033 | P22: 924 | Q22: 0 | R22: 691
A23: 11 | B23: Guanajuato | C23: 6 | D23: 1147026 | E23: 329221 | F23: 39086 | G23: 95361 | H23: 0 | I23: 0 | J23: 13516 | K23: 0 | L23: 0 | M23: 3186 | N23: 1795 | O23: 6293 | P23: 5075 | Q23: 0 | R23: 4408
A24: 12 | B24: Guerrero | C24: 0 | D24: 177830 | E24: 55238 | F24: 10635 | G24: 132415 | H24: 0 | I24: 0 | J24: 6164 | K24: 0 | L24: 0 | M24: 0 | N24: 0 | O24: 5903 | P24: 1276 | Q24: 0 | R24: 0
A25: 13 | B25: Hidalgo | C25: 3388 | D25: 252774 | E25: 140828 | F25: 0 | G25: 10391 | H25: 0 | I25: 0 | J25: 17505 | K25: 0 | L25: 0 | M25: 3037 | N25: 584 | O25: 11383 | P25: 364 | Q25: 0 | R25: 0
... A48: 40 | B48: D.F. Sur | C48: 1451 | D48: 1773547 | E48: 671494 | F48: 35126 | G48: 421252 | H48: 0 | I48: 0 | J48: 22551 | K48: 0 | L48: 0 | M48: 8596 | N48: 16216 | O48: 98443 | P48: 26767 | Q48: 0 | R48: 104367
A49: Total UMAE | C49: =SUM(C50:C74) -> 12359 | D49: =SUM(D50:D74) -> 64375 | E49: =SUM(E50:E74) -> 1210554 | F49: =SUM(F50:F74) -> 94852 | G49: =SUM(G50:G74) -> 982592 | H49: =SUM(H50:H74) -> 0 | I49: =SUM(I50:I74) -> 0 | J49: =SUM(J50:J74) -> 466039 | ... R49: =SUM(R50:R74) -> 146828
A50: 4A | B50: UMAE 1 CMN LA RAZA | C50: 0 | D50: 0 | E50: 0 | F50: 4492 | G50: 3809 | H50: 0 | I50: 0 | J50: 18834 | K50: 0 | L50: 757 | M50: 0 | N50: 0 | O50: 2497 | P50: 462 | Q50: 1365 | R50: 9456
A51: 4B | B51: UMAE 2 CMN S XXI | C51: 0 | D51: 0 | E51: 0 | F51: 6446 | G51: 29557 | H51: 0 | I51: 0 | J51: 3299 | K51: 0 | L51: 0 | M51: 0 | N51: 879 | O51: 3774 | P51: 2711 | Q51: 5293 | R51: 41598
A52: 4C | B52: UMAE 3 CMN OCC | C52: 0 | D52: 0 | E52: 50653 | F52: 12319 | G52: 0 | H52: 0 | I52: 0 | J52: 40413 | K52: 25024 | L52: 10974 | M52: 2143 | N52: 0 | O52: 2433 | P52: 2677 | Q52: 0 | R52: 15765
A53: 4D | B53: UMAE 4 CMN MTY | C53: 0 | D53: 78 | E53: 0 | F53: 7413 | G53: 202709 | H53: 0 | I53: 0 | J53: 49431 | K53: 45657 | L53: 735 | M53: 0 | N53: 955 | O53: 5952 | P53: 5939 | Q53: 0 | R53: 0
A54: 4E | B54: UMAE 5 TORREON | C54: 0 | D54: 1772 | E54: 1797 | F54: 3679 | G54: 18936 | H54: 0 | I54: 0 | J54: 26875 | K54: 18107 | L54: 0 | M54: 0 | N54: 288 | O54: 0 | P54: 857 | Q54: 0 | R54: 0
A55: 4F | B55: UMAE 6 CMN PUEBLA | C55: 0 | D55: 0 | E55: 81229 | F55: 726 | G55: 29375 | H55: 0 | I55: 0 | J55: 31767 | K55: 149563 | L55: 20862 | M55: 1300 | N55: 3039 | O55: 33722 | P55: 2247 | Q55: 0 | R55: 0
A56: 4G | B56: UMAE 7 CMN BAJIO | C56: 0 | D56: 0 | E56: 58576 | F56: 11116 | G56: 32789 | H56: 0 | I56: 0 | J56: 15139 | K56: 10450 | L56: 0 | M56: 0 | N56: 1654 | O56: 4469 | P56: 797 | Q56: 0 | R56: 145
A57: 4H | B57: UMAE 8 CMN OBREGON | C57: 0 | D57: 6957 | E57: 47113 | F57: 30574 | G57: 0 | H57: 0 | I57: 0 | J57: 0 | K57: 0 | L57: 0 | M57: 6736 | N57: 955 | O57: 8332 | P57: 0 | Q57: 0 | R57: 0
A58: 4I | B58: UMAE 9 CMN VERACRUZ | C58: 0 | D58: 11023 | E58: 79785 | F58: 7026 | G58: 11582 | H58: 0 | I58: 0 | J58: 15052 | K58: 0 | L58: 0 | M58: 2101 | N58: 710 | O58: 16537 | P58: 575 | Q58: 0 | R58: 0
A59: 4J | B59: UMAE 10 CMN MERIDA | C59: 0 | D59: 0 | E59: 0 | F59: 0 | G59: 0 | H59: 0 | I59: 0 | J59: 11231 | K59: 23019 | L59: 0 | M59: 0 | N59: 0 | O59: 0 | P59: 0 | Q59: 0 | R59: 0
A60: 4K | B60: UMAE 11 CMN LA RAZA | C60: 125 | D60: 0 | E60: 0 | F60: 0 | G60: 14037 | H60: 0 | I60: 0 | J60: 16784 | K60: 0 | L60: 0 | M60: 0 | N60: 0 | O60: 0 | P60: 0 | Q60: 0 | R60: 0
A61: 4L | B61: UMAE 12 SAN ANGEL | C61: 3344 | D61: 0 | E61: 0 | F61: 0 | G61: 34031 | H61: 0 | I61: 0 | J61: 15314 | K61: 0 | L61: 0 | M61: 0 | N61: 0 | O61: 0 | P61: 0 | Q61: 0 | R61: 0
... A74: 4Y | B74: UMAE 25 CMN SIGLO XXI | C74: 0 | D74: 0 | E74: 1670 | F74: 0 | G74: 17693 | H74: 0 | I74: 0 | J74: 80743 | K74: 50828 | L74: 0 | M74: 1605 | N74: 0 | O74: 0 | P74: 3862 | Q74: 0 | R74: 6755

Sheet 33 Procedimientos
A7: =CONCATENATE("33 Procedimientos fuera de Quirófano, ",Control!B4) -> 33 Procedimientos fuera de Quirófano, Diciembre 2025
A8: Fuente: DataMart Estadísticas Médicas (Se presentan las cifras al cierre de mayo 2022 debido a la falla general que se presentó dicha plataforma)
A10: Clave | B10: Nombre OOAD o UMAE | C10: 33 Procedimientos fuera de Quirofáno
C11: ABORDAJE ENDOVASCULAR MENOR | D11: ASISTENCIA Y SOPORTE VENTILATORIO INVASIVO Y NO INVASIVO | E11: BIOPSIA DE CÉRVIX | F11: BIOPSIA DE ENDOMETRIO | G11: BIOPSIA DE HÍGADO | H11: BIOPSIA DE MAMA | I11: BIOPSIA DE RIÑÓN | J11: BIOPSIA DE TIROIDES | K11: CAMBIO DE LÍNEA DE TRANSFERENCIA DEL CATETER TENCKHOFF | L11: CAMPIMETRÍA | M11: CARDIOTOCOGRAFÍA | N11: CARDIOVERSIÓN DESFIBRILACIÓN | O11: COLANGIOPANCREATOGRAFÍA RETRÓGRADA ENDOSCÓPICA (CPRE) | P11: COLOCACIÓN DE CATÉTER DE TENCKHOFF PERCUTÁNEO | Q11: COLOCACIÓN DE CATÉTER PARA HEMODIÁLISIS | R11: COLOCACIÓN DE SONDAS | S11: COLONOSCOPÍA | T11: COLPOSCOPÍA | U11: CURACIONES | V11: DRENAJE PERCUTÁNEO DE ABSCESOS | W11: ECOSONOGRAFÍA DOPPLER | X11: ECOSONOGRAFÍA OFTALMOLÓGICA | Y11: INTERCONSULTAS | Z11: MADURACIÓN CERVICAL PRE-INDUCCIÓN | AA11: MARCAPASOS TEMPORALES | AB11: MASTOGRAFÍA | AC11: NUTRICIÓN PARENTERAL | AD11: OTRAS BIOPSIAS | AE11: PARACENTESIS / TORACOCENTESIS / AMNIOCENTESIS / ARTROCENTESIS | AF11: PUNCIÓN LUMBAR | AG11: REDUCCIÓN DE FRACTURAS | AH11: SUTURAS | AI11: URODINAMIA
A12: Nacional | C12: =+SUM(C13+C49) -> 1685180 | D12: =+SUM(D13+D49) -> 1219379 | E12: =+SUM(E13+E49) -> 56875 | F12: =+SUM(F13+F49) -> 23452 | G12: =+SUM(G13+G49) -> 2762 | H12: =+SUM(H13+H49) -> 44790 | I12: =+SUM(I13+I49) -> 5263 | J12: =+SUM(J13+J49) -> 11344 | ... AI12: =+SUM(AI13+AI49) -> 3927
A13: Total Delegaciones (Primer y Segundo Nivel) | C13: =+SUM(C14:C48) -> 1369935 | D13: =+SUM(D14:D48) -> 886642 | E13: =+SUM(E14:E48) -> 53876 | F13: =+SUM(F14:F48) -> 19407 | G13: =+SUM(G14:G48) -> 1229 | H13: =+SUM(H14:H48) -> 33753 | I13: =+SUM(I14:I48) -> 1865 | J13: =+SUM(J14:J48) -> 5615 | ... AI13: =+SUM(AI14:AI48) -> 883
A14: 01 | B14: Aguascalientes | C14: 32494 | D14: 7803 | E14: 1336 | F14: 542 | G14: 100 | H14: 572 | I14: 74 | J14: 149 | K14: 1028 | L14: 721 | M14: 9076 | N14: 2327 | O14: 1165 | P14: 234 | Q14: 357 | R14: 19684 | S14: 862 | T14: 4212 | U14: 75747 | V14: 50 | W14: 6569 | X14: 0 | Y14: 7535 | Z14: 2794 | AA14: 129 | AB14: 7324 | AC14: 3505 | AD14: 11517 | AE14: 919 | AF14: 2965 | AG14: 4896 | AH14: 15057 | AI14: 0
A15: 02 | B15: Baja California | C15: 90619 | D15: 125181 | E15: 2599 | F15: 714 | G15: 29 | H15: 1849 | I15: 56 | J15: 241 | K15: 1554 | L15: 329 | M15: 7683 | N15: 560 | O15: 50 | P15: 201 | Q15: 1036 | R15: 48440 | S15: 476 | T15: 11086 | U15: 206397 | V15: 417 | W15: 2727 | X15: 0 | Y15: 16294 | Z15: 1744 | AA15: 63 | AB15: 63664 | AC15: 5219 | AD15: 3593 | AE15: 3083 | AF15: 680 | AG15: 4726 | AH15: 26815 | AI15: 0
A16: 03 | B16: Baja California Sur | C16: 724 | D16: 168 | E16: 688 | F16: 159 | G16: 1 | H16: 306 | I16: 0 | J16: 2 | K16: 428 | L16: 2020 | M16: 2322 | N16: 44 | O16: 160 | P16: 82 | Q16: 336 | R16: 2574 | S16: 608 | T16: 2520 | U16: 37059 | V16: 250 | W16: 466 | X16: 0 | Y16: 3307 | Z16: 1066 | AA16: 11 | AB16: 9002 | AC16: 1375 | AD16: 2291 | AE16: 98 | AF16: 0 | AG16: 464 | AH16: 3841 | AI16: 0
A17: 04 | B17: Campeche | C17: 29543 | D17: 1815 | E17: 282 | F17: 16 | G17: 0 | H17: 134 | I17: 0 | J17: 0 | K17: 484 | L17: 1209 | M17: 944 | N17: 62 | O17: 0 | P17: 0 | Q17: 173 | R17: 7212 | S17: 39 | T17: 1476 | U17: 47363 | V17: 296 | W17: 0 | X17: 0 | Y17: 15157 | Z17: 143 | AA17: 24 | AB17: 6738 | AC17: 0 | AD17: 150 | AE17: 86 | AF17: 24 | AG17: 98 | AH17: 3837 | AI17: 0
A18: 05 | B18: Coahuila | C18: 100857 | D18: 4094 | E18: 906 | F18: 486 | G18: 16 | H18: 1384 | I18: 18 | J18: 13 | K18: 1795 | L18: 290 | M18: 8415 | N18: 1580 | O18: 0 | P18: 993 | Q18: 927 | R18: 29766 | S18: 253 | T18: 5407 | U18: 229091 | V18: 190 | W18: 7752 | X18: 16 | Y18: 39477 | Z18: 3708 | AA18: 239 | AB18: 61662 | AC18: 2991 | AD18: 2977 | AE18: 863 | AF18: 183 | AG18: 5845 | AH18: 29421 | AI18: 18
A19: 06 | B19: Colima | C19: 1474 | D19: 87661 | E19: 0 | F19: 0 | G19: 7 | H19: 348 | I19: 1 | J19: 132 | K19: 290 | L19: 41 | M19: 0 | N19: 13 | O19: 294 | P19: 16 | Q19: 330 | R19: 5393 | S19: 1274 | T19: 0 | U19: 55450 | V19: 246 | W19: 1416 | X19: 0 | Y19: 1905 | Z19: 217 | AA19: 0 | AB19: 11893 | AC19: 555 | AD19: 1519 | AE19: 142 | AF19: 119 | AG19: 272 | AH19: 4393 | AI19: 0
A20: 07 | B20: Chiapas | C20: 22226 | D20: 3185 | E20: 772 | F20: 340 | G20: 0 | H20: 359 | I20: 0 | J20: 0 | K20: 1087 | L20: 1092 | M20: 1196 | N20: 379 | O20: 0 | P20: 558 | Q20: 265 | R20: 7245 | S20: 1334 | T20: 6572 | U20: 68844 | V20: 2500 | W20: 175 | X20: 0 | Y20: 13701 | Z20: 82 | AA20: 13 | AB20: 14544 | AC20: 1296 | AD20: 1116 | AE20: 250 | AF20: 106 | AG20: 475 | AH20: 3412 | AI20: 110
A21: 08 | B21: Chihuahua | C21: 6208 | D21: 2511 | E21: 1225 | F21: 612 | G21: 11 | H21: 1246 | I21: 22 | J21: 71 | K21: 1839 | L21: 2 | M21: 9091 | N21: 707 | O21: 84 | P21: 454 | Q21: 948 | R21: 43383 | S21: 323 | T21: 5296 | U21: 107470 | V21: 1464 | W21: 8131 | X21: 427 | Y21: 36193 | Z21: 366 | AA21: 131 | AB21: 40956 | AC21: 6575 | AD21: 3548 | AE21: 1536 | AF21: 2287 | AG21: 1672 | AH21: 20403 | AI21: 16
A22: 10 | B22: Durango | C22: 13816 | D22: 3373 | E22: 146 | F22: 28 | G22: 0 | H22: 335 | I22: 0 | J22: 0 | K22: 844 | L22: 0 | M22: 2606 | N22: 1240 | O22: 0 | P22: 0 | Q22: 236 | R22: 13106 | S22: 79 | T22: 3155 | U22: 62149 | V22: 216 | W22: 777 | X22: 133 | Y22: 12940 | Z22: 1588 | AA22: 24 | AB22: 12670 | AC22: 2346 | AD22: 202 | AE22: 242 | AF22: 7 | AG22: 1429 | AH22: 18176 | AI22: 0
A23: 11 | B23: Guanajuato | C23: 8695 | D23: 6138 | E23: 369 | F23: 737 | G23: 47 | H23: 575 | I23: 10 | J23: 236 | K23: 2415 | L23: 483 | M23: 1298 | N23: 366 | O23: 424 | P23: 635 | Q23: 871 | R23: 22503 | S23: 1518 | T23: 4367 | U23: 119831 | V23: 205 | W23: 6674 | X23: 115 | Y23: 20145 | Z23: 422 | AA23: 103 | AB23: 26638 | AC23: 2283 | AD23: 3556 | AE23: 229 | AF23: 1042 | AG23: 7289 | AH23: 22463 | AI23: 393
A24: 12 | B24: Guerrero | C24: 114 | D24: 149 | E24: 431 | F24: 112 | G24: 25 | H24: 291 | I24: 0 | J24: 28 | K24: 348 | L24: 0 | M24: 13 | N24: 46 | O24: 20 | P24: 106 | Q24: 12 | R24: 3078 | S24: 180 | T24: 1215 | U24: 23830 | V24: 99 | W24: 868 | X24: 0 | Y24: 1602 | Z24: 28 | AA24: 0 | AB24: 10008 | AC24: 16 | AD24: 438 | AE24: 45 | AF24: 4 | AG24: 372 | AH24: 4302 | AI24: 98
A25: 13 | B25: Hidalgo | C25: 33734 | D25: 15229 | E25: 5554 | F25: 22 | G25: 5 | H25: 731 | I25: 7 | J25: 369 | K25: 1804 | L25: 813 | M25: 2443 | N25: 216 | O25: 247 | P25: 706 | Q25: 404 | R25: 20508 | S25: 881 | T25: 6974 | U25: 65833 | V25: 67 | W25: 6977 | X25: 0 | Y25: 16343 | Z25: 106 | AA25: 6 | AB25: 10600 | AC25: 5132 | AD25: 899 | AE25: 89 | AF25: 99 | AG25: 1152 | AH25: 10554 | AI25: 0
... A48: 40 | B48: CDMX Sur | C48: 38471 | D48: 16263 | E48: 3325 | F48: 2550 | G48: 47 | H48: 4349 | I48: 147 | J48: 573 | K48: 3728 | L48: 1770 | M48: 6887 | N48: 377 | O48: 1264 | P48: 1452 | Q48: 1954 | R48: 48412 | S48: 5098 | T48: 8436 | U48: 543725 | V48: 189 | W48: 13341 | X48: 808 | Y48: 54290 | Z48: 1014 | AA48: 5 | AB48: 87205 | AC48: 5062 | AD48: 31756 | AE48: 859 | AF48: 654 | AG48: 2000 | AH48: 41316 | AI48: 0
A49: Total UMAE | C49: =+SUM(C50:C74) -> 315245 | D49: =+SUM(D50:D74) -> 332737 | E49: =+SUM(E50:E74) -> 2999 | F49: =+SUM(F50:F74) -> 4045 | G49: =+SUM(G50:G74) -> 1533 | H49: =+SUM(H50:H74) -> 11037 | I49: =+SUM(I50:I74) -> 3398 | J49: =+SUM(J50:J74) -> 5729 | ... AI49: =+SUM(AI50:AI74) -> 3044
A50: 4A | B50: UMAE 01 HES CMN La Raza | C50: 36645 | D50: 6107 | E50: 0 | F50: 345 | G50: 132 | H50: 0 | I50: 505 | J50: 2051 | K50: 0 | L50: 0 | M50: 0 | N50: 241 | O50: 1782 | P50: 17 | Q50: 1600 | R50: 6983 | S50: 2332 | T50: 0 | U50: 15658 | V50: 625 | W50: 2979 | X50: 762 | Y50: 41396 | Z50: 9 | AA50: 465 | AB50: 0 | AC50: 2591 | AD50: 5222 | AE50: 1149 | AF50: 550 | AG50: 0 | AH50: 8807 | AI50: 214
A51: 4B | B51: UMAE 02 HE CMN Siglo XXI | C51: 6736 | D51: 0 | E51: 2 | F51: 9 | G51: 59 | H51: 36 | I51: 155 | J51: 335 | K51: 61 | L51: 764 | M51: 5 | N51: 4 | O51: 2374 | P51: 9 | Q51: 122 | R51: 1636 | S51: 3670 | T51: 35 | U51: 21156 | V51: 53 | W51: 1803 | X51: 1369 | Y51: 16432 | Z51: 5 | AA51: 1 | AB51: 451 | AC51: 5768 | AD51: 353 | AE51: 223 | AF51: 395 | AG51: 5 | AH51: 1268 | AI51: 1018
A52: 4C | B52: UMAE 03 HE CMN Occidente | C52: 12529 | D52: 34259 | E52: 0 | F52: 0 | G52: 0 | H52: 3 | I52: 417 | J52: 37 | K52: 0 | L52: 531 | M52: 0 | N52: 378 | O52: 192 | P52: 0 | Q52: 757 | R52: 7820 | S52: 1323 | T52: 0 | U52: 51923 | V52: 4824 | W52: 0 | X52: 0 | Y52: 72582 | Z52: 0 | AA52: 2246 | AB52: 1542 | AC52: 3946 | AD52: 3824 | AE52: 1468 | AF52: 2160 | AG52: 696 | AH52: 5533 | AI52: 0
A53: 4D | B53: UMAE 04 HE Monterrey | C53: 3034 | D53: 3571 | E53: 0 | F53: 0 | G53: 240 | H53: 18 | I53: 101 | J53: 417 | K53: 0 | L53: 632 | M53: 0 | N53: 158 | O53: 208 | P53: 0 | Q53: 98 | R53: 11126 | S53: 448 | T53: 0 | U53: 19558 | V53: 103 | W53: 3571 | X53: 0 | Y53: 14542 | Z53: 0 | AA53: 0 | AB53: 168 | AC53: 1238 | AD53: 878 | AE53: 383 | AF53: 1746 | AG53: 226 | AH53: 9768 | AI53: 92
A54: 4E | B54: UMAE 05 HE Torreón | C54: 25239 | D54: 15773 | E54: 4 | F54: 8 | G54: 77 | H54: 326 | I54: 85 | J54: 297 | K54: 34 | L54: 1675 | M54: 0 | N54: 1251 | O54: 738 | P54: 8 | Q54: 167 | R54: 3697 | S54: 943 | T54: 0 | U54: 23858 | V54: 0 | W54: 979 | X54: 0 | Y54: 7808 | Z54: 0 | AA54: 451 | AB54: 1637 | AC54: 4945 | AD54: 1 | AE54: 99 | AF54: 499 | AG54: 0 | AH54: 3266 | AI54: 372
A55: 4F | B55: UMAE 06 HE Puebla | C55: 130 | D55: 387 | E55: 166 | F55: 178 | G55: 468 | H55: 2647 | I55: 718 | J55: 1116 | K55: 0 | L55: 120 | M55: 0 | N55: 0 | O55: 301 | P55: 0 | Q55: 91 | R55: 1270 | S55: 654 | T55: 610 | U55: 5382 | V55: 0 | W55: 2856 | X55: 3363 | Y55: 6509 | Z55: 1136 | AA55: 662 | AB55: 2019 | AC55: 1096 | AD55: 3698 | AE55: 196 | AF55: 720 | AG55: 0 | AH55: 51 | AI55: 0
A56: 4G | B56: UMAE 07 HE CMN del Bajío | C56: 1930 | D56: 5880 | E56: 0 | F56: 0 | G56: 0 | H56: 0 | I56: 97 | J56: 109 | K56: 0 | L56: 1189 | M56: 0 | N56: 0 | O56: 182 | P56: 0 | Q56: 137 | R56: 2829 | S56: 791 | T56: 0 | U56: 13216 | V56: 0 | W56: 734 | X56: 2791 | Y56: 10326 | Z56: 0 | AA56: 248 | AB56: 0 | AC56: 2104 | AD56: 628 | AE56: 144 | AF56: 458 | AG56: 0 | AH56: 0 | AI56: 0
A57: 4H | B57: UMAE 08 HE Obregón | C57: 15266 | D57: 9557 | E57: 0 | F57: 0 | G57: 15 | H57: 3 | I57: 11 | J57: 18 | K57: 159 | L57: 634 | M57: 0 | N57: 146 | O57: 108 | P57: 62 | Q57: 327 | R57: 2194 | S57: 675 | T57: 0 | U57: 63250 | V57: 19 | W57: 2249 | X57: 2166 | Y57: 16509 | Z57: 0 | AA57: 282 | AB57: 0 | AC57: 840 | AD57: 154 | AE57: 268 | AF57: 43 | AG57: 0 | AH57: 295 | AI57: 0
A58: 4I | B58: UMAE 09 HE Veracruz | C58: 15422 | D58: 2973 | E58: 0 | F58: 0 | G58: 34 | H58: 13 | I58: 85 | J58: 347 | K58: 312 | L58: 235 | M58: 0 | N58: 99 | O58: 34 | P58: 62 | Q58: 742 | R58: 2844 | S58: 305 | T58: 0 | U58: 32472 | V58: 111 | W58: 2323 | X58: 740 | Y58: 7956 | Z58: 0 | AA58: 229 | AB58: 0 | AC58: 1899 | AD58: 471 | AE58: 325 | AF58: 581 | AG58: 673 | AH58: 2387 | AI58: 0
A59: 4J | B59: UMAE 10 HE 1 Merida | C59: 0 | D59: 0 | E59: 2 | F59: 3 | G59: 14 | H59: 23 | I59: 31 | J59: 23 | K59: 0 | L59: 0 | M59: 0 | N59: 0 | O59: 0 | P59: 0 | Q59: 0 | R59: 0 | S59: 0 | T59: 0 | U59: 0 | V59: 0 | W59: 2315 | X59: 0 | Y59: 588 | Z59: 0 | AA59: 124 | AB59: 741 | AC59: 6456 | AD59: 292 | AE59: 0 | AF59: 0 | AG59: 0 | AH59: 0 | AI59: 0
A60: 4K | B60: UMAE 11 HGO CMN La Raza | C60: 5217 | D60: 12390 | E60: 180 | F60: 327 | G60: 0 | H60: 4394 | I60: 0 | J60: 0 | K60: 0 | L60: 0 | M60: 10520 | N60: 0 | O60: 0 | P60: 0 | Q60: 0 | R60: 8729 | S60: 0 | T60: 1213 | U60: 22786 | V60: 0 | W60: 368 | X60: 0 | Y60: 5850 | Z60: 498 | AA60: 0 | AB60: 9496 | AC60: 12 | AD60: 1534 | AE60: 305 | AF60: 0 | AG60: 0 | AH60: 0 | AI60: 711
A61: 4L | B61: UMAE 12 HGO San Angel | C61: 10344 | D61: 2013 | E61: 681 | F61: 2122 | G61: 0 | H61: 122 | I61: 0 | J61: 0 | K61: 0 | L61: 0 | M61: 28121 | N61: 0 | O61: 0 | P61: 30 | Q61: 0 | R61: 383964 | S61: 0 | T61: 4635 | U61: 6487 | V61: 60 | W61: 34756 | X61: 0 | Y61: 7671 | Z61: 5370 | AA61: 0 | AB61: 3200 | AC61: 3930 | AD61: 2753 | AE61: 243 | AF61: 0 | AG61: 1 | AH61: 57 | AI61: 446
... A74: 4Y | B74: UMAE 25 HOnco CMN Siglo XXI | C74: 0 | D74: 1798 | E74: 186 | F74: 242 | G74: 225 | H74: 1072 | I74: 441 | J74: 701 | K74: 0 | L74: 0 | M74: 0 | N74: 0 | O74: 238 | P74: 0 | Q74: 0 | R74: 3474 | S74: 1851 | T74: 56 | U74: 20191 | V74: 0 | W74: 486 | X74: 0 | Y74: 3543 | Z74: 0 | AA74: 0 | AB74: 4434 | AC74: 871 | AD74: 7133 | AE74: 869 | AF74: 0 | AG74: 0 | AH74: 2776 | AI74: 0

Sheet Atenciones Prof. de Salud
A7: =CONCATENATE("Atenciones Profesionales de Salud, ",Control!B4) -> Atenciones Profesionales de Salud, Diciembre 2025
A8: Fuente: SUI 27, Motivos de Demanda de la Consulta Externa
A10: Clave | B10: Nombre OOAD o UMAE | D10: Atenciones Profesionales de Salud
D11: Total ** | E11: Trabajo Social | F11: Psicología | G11: Optometría | H11: Nutrición y Dietética | I11: Enfermera Prenatal de Hospital | J11: Enfermera Materno Infantil | K11: Enfermera Crónico-Degenerativo | L11: Terapia física, ocupacional y de fonoaudiología | M11: Enfermera Especialista Geriátrica | N11: Diagnóstico por Imagen | O11: Evaluación Diagnóstica | P11: Parteras Rurales | Q11: Rehabilitación Integral | S11: Psicología | T11: Optometría | U11: Nutrición y Dietética | V11: Enfermera Prenatal de Hospital | W11: Enfermera Materno Infantil | X11: Enfermera Crónico-Degenerativo
A12: Nacional | D12: =+SUM(D13+D49) -> 7881875 | E12: =+SUM(E13+E49) -> 5668944 | F12: =+SUM(F13+F49) -> 272346 | G12: =+SUM(G13+G49) -> 26475 | H12: =+SUM(H13+H49) -> 365843 | I12: =+SUM(I13+I49) -> 94655 | J12: =+SUM(J13+J49) -> 4182 | K12: =+SUM(K13+K49) -> 11141 | ... Q12: =+SUM(Q13+Q49) -> 0
A13: Total Delegaciones (Primer y Segundo Nivel) | D13: =+SUM(D14:D48) -> 6737486 | E13: =+SUM(E14:E48) -> 4802587 | F13: =+SUM(F14:F48) -> 216245 | G13: =+SUM(G14:G48) -> 26475 | H13: =+SUM(H14:H48) -> 321689 | I13: =+SUM(I14:I48) -> 72057 | J13: =+SUM(J14:J48) -> 4182 | K13: =+SUM(K14:K48) -> 11141 | ... Q13: =+SUM(Q14:Q48) -> 0
A14: 01 | B14: Aguascalientes | C14: 69018 | D14: 177983 | E14: 99952 | F14: 2677 | G14: 0 | H14: 7025 | I14: 1214 | J14: 1190 | K14: 0 | L14: 63185 | M14: 2740 | N14: 0 | O14: 0 | P14: 0 | Q14: 0
A15: 02 | B15: Baja California | C15: 134162 | D15: 312931 | E15: 252062 | F15: 7872 | G15: 0 | H15: 2747 | I15: 0 | J15: 0 | K15: 0 | L15: 47537 | M15: 2713 | N15: 0 | O15: 7888 | P15: 0 | Q15: 0
A16: 03 | B16: Baja California Sur | C16: 23712 | D16: 67784 | E16: 60587 | F16: 3041 | G16: 0 | H16: 1910 | I16: 0 | J16: 0 | K16: 0 | L16: 0 | M16: 2246 | N16: 0 | O16: 0 | P16: 0 | Q16: 0
A17: 04 | B17: Campeche | C17: 19547 | D17: 64272 | E17: 39576 | F17: 428 | G17: 0 | H17: 958 | I17: 502 | J17: 0 | K17: 0 | L17: 20062 | M17: 2746 | N17: 0 | O17: 0 | P17: 0 | Q17: 0
A18: 05 | B18: Coahuila | C18: 93305 | D18: 216437 | E18: 192498 | F18: 6262 | G18: 0 | H18: 13896 | I18: 0 | J18: 0 | K18: 0 | L18: 0 | M18: 3781 | N18: 0 | O18: 4260 | P18: 0 | Q18: 0
A19: 06 | B19: Colima | C19: 20282 | D19: 60837 | E19: 43341 | F19: 4768 | G19: 0 | H19: 4147 | I19: 0 | J19: 0 | K19: 0 | L19: 2034 | M19: 6547 | N19: 0 | O19: 0 | P19: 0 | Q19: 0
A20: 07 | B20: Chiapas | C20: 31320 | D20: 75103 | E20: 62031 | F20: 5730 | G20: 0 | H20: 1958 | I20: 1661 | J20: 0 | K20: 2540 | L20: 0 | M20: 1183 | N20: 0 | O20: 0 | P20: 0 | Q20: 0
A21: 08 | B21: Chihuahua | C21: 123868 | D21: 353828 | E21: 263849 | F21: 9199 | G21: 1174 | H21: 12932 | I21: 7521 | J21: 0 | K21: 0 | L21: 57845 | M21: 1308 | N21: 137 | O21: 5779 | P21: 0 | Q21: 0
A22: 10 | B22: Durango | C22: 68371 | D22: 181105 | E22: 152191 | F22: 1294 | G22: 0 | H22: 21619 | I22: 3469 | J22: 0 | K22: 0 | L22: 0 | M22: 2532 | N22: 0 | O22: 0 | P22: 0 | Q22: 0
A23: 11 | B23: Guanajuato | C23: 56170 | D23: 128598 | E23: 114471 | F23: 3219 | G23: 0 | H23: 6402 | I23: 4496 | J23: 0 | K23: 0 | L23: 10 | M23: 0 | N23: 0 | O23: 0 | P23: 0 | Q23: 0
A24: 12 | B24: Guerrero | C24: 19217 | D24: 71538 | E24: 28777 | F24: 3027 | G24: 0 | H24: 3256 | I24: 0 | J24: 0 | K24: 0 | L24: 35594 | M24: 884 | N24: 0 | O24: 0 | P24: 0 | Q24: 0
A25: 13 | B25: Hidalgo | C25: 96225 | D25: 281128 | E25: 201559 | F25: 5434 | G25: 2437 | H25: 3032 | I25: 0 | J25: 0 | K25: 1276 | L25: 67390 | M25: 0 | N25: 0 | O25: 0 | P25: 0 | Q25: 0
A26: 14 | B26: Jalisco | C26: 181743 | D26: 403880 | E26: 240957 | F26: 17024 | G26: 0 | H26: 23357 | I26: 10387 | J26: 2992 | K26: 740 | L26: 100265 | M26: 8158 | N26: 0 | O26: 7433 | P26: 0 | Q26: 0
A27: 15 | B27: México Oriente | C27: 209185 | D27: 502287 | E27: 414121 | F27: 17779 | G27: 6297 | H27: 33934 | I27: 9721 | J27: 0 | K27: 0 | L27: 14650 | M27: 5785 | N27: 110 | O27: 5398 | P27: 0 | Q27: 0
A28: 16 | B28: México Poniente | C28: 93143 | D28: 215755 | E28: 188150 | F28: 9645 | G28: 0 | H28: 12733 | I28: 1205 | J28: 0 | K28: 0 | L28: 0 | M28: 4022 | N28: 0 | O28: 0 | P28: 0 | Q28: 0
A29: 17 | B29: Michoacán | C29: 60145 | D29: 195997 | E29: 118005 | F29: 4309 | G29: 0 | H29: 5666 | I29: 1680 | J29: 0 | K29: 1669 | L29: 55798 | M29: 8870 | N29: 0 | O29: 0 | P29: 0 | Q29: 0
A30: 18 | B30: Morelos | C30: 23886 | D30: 69926 | E30: 60926 | F30: 0 | G30: 0 | H30: 7423 | I30: 0 | J30: 0 | K30: 0 | L30: 0 | M30: 1577 | N30: 0 | O30: 0 | P30: 0 | Q30: 0
A31: 19 | B31: Nayarit | C31: 53158 | D31: 116364 | E31: 106146 | F31: 3191 | G31: 0 | H31: 6072 | I31: 0 | J31: 0 | K31: 0 | L31: 35 | M31: 920 | N31: 0 | O31: 0 | P31: 0 | Q31: 0
A32: 20 | B32: Nuevo León | C32: 154545 | D32: 379615 | E32: 319533 | F32: 7873 | G32: 0 | H32: 8764 | I32: 1355 | J32: 0 | K32: 0 | L32: 35757 | M32: 6333 | N32: 0 | O32: 0 | P32: 0 | Q32: 0
A33: 21 | B33: Oaxaca | C33: 14039 | D33: 38732 | E33: 30729 | F33: 916 | G33: 1636 | H33: 3775 | I33: 0 | J33: 0 | K33: 0 | L33: 0 | M33: 1676 | N33: 0 | O33: 0 | P33: 0 | Q33: 0
... A48: 40 | B48: Ciudad de México Sur | C48: 127115 | D48: 331365 | E48: 269730 | F48: 28469 | G48: 558 | H48: 24302 | I48: 0 | J48: 0 | K48: 0 | L48: 146 | M48: 8160 | N48: 13 | O48: 13109 | P48: 0 | Q48: 0
A49: Total UMAE | D49: =+SUM(D50:D74) -> 1144389 | E49: =+SUM(E50:E74) -> 866357 | F49: =+SUM(F50:F74) -> 56101 | G49: =+SUM(G50:G74) -> 0 | H49: =+SUM(H50:H74) -> 44154 | I49: =+SUM(I50:I74) -> 22598 | J49: =+SUM(J50:J74) -> 0 | K49: =+SUM(K50:K74) -> 0 | ... O49: =+SUM(O50:O74) -> 0
A50: 4A | B50: UMAE 01 HES CMN La Raza | C50: 7807 | D50: 18268 | E50: 10894 | F50: 6603 | G50: 0 | H50: 667 | I50: 0 | J50: 0 | K50: 0 | L50: 0 | M50: 104 | N50: 0 | O50: 0 | P50: 0 | Q50: 0
A51: 4B | B51: UMAE 02 HES CMN Siglo XXI | C51: 28207 | D51: 49174 | E51: 43035 | F51: 2813 | G51: 0 | H51: 1439 | I51: 0 | J51: 0 | K51: 0 | L51: 0 | M51: 1887 | N51: 0 | O51: 0 | P51: 0 | Q51: 0
A52: 4C | B52: UMAE 03 HES CMN Occidente | C52: 45004 | D52: 95336 | E52: 58221 | F52: 1647 | G52: 0 | H52: 1054 | I52: 0 | J52: 0 | K52: 0 | L52: 32680 | M52: 1734 | N52: 0 | O52: 0 | P52: 0 | Q52: 0
A53: 4D | B53: UMAE 04 HES Monterrey | C53: 17494 | D53: 76370 | E53: 65185 | F53: 6554 | G53: 0 | H53: 1797 | I53: 0 | J53: 0 | K53: 0 | L53: 0 | M53: 2834 | N53: 0 | O53: 0 | P53: 0 | Q53: 0
A54: 4E | B54: UMAE 05 HES Torreón | C54: 18711 | D54: 57828 | E54: 49714 | F54: 3998 | G54: 0 | H54: 2279 | I54: 0 | J54: 0 | K54: 0 | L54: 0 | M54: 1837 | N54: 0 | O54: 0 | P54: 0 | Q54: 0
A55: 4F | B55: UMAE 06 HES Puebla | C55: 1366 | D55: 22575 | E55: 17881 | F55: 1400 | G55: 0 | H55: 1618 | I55: 0 | J55: 0 | K55: 0 | L55: 0 | M55: 1676 | N55: 0 | O55: 0 | P55: 0 | Q55: 0
A56: 4G | B56: UMAE 07 HES CMN del Bajío | C56: 13332 | D56: 29924 | E56: 25496 | F56: 1531 | G56: 0 | H56: 1595 | I56: 0 | J56: 0 | K56: 0 | L56: 0 | M56: 1302 | N56: 0 | O56: 0 | P56: 0 | Q56: 0
A57: 4H | B57: UMAE 08 HES Obregón | C57: 10280 | D57: 25355 | E57: 21702 | F57: 461 | G57: 0 | H57: 1337 | I57: 0 | J57: 0 | K57: 0 | L57: 0 | M57: 1855 | N57: 0 | O57: 0 | P57: 0 | Q57: 0
A58: 4I | B58: UMAE 09 HES Veracruz | C58: 36885 | D58: 68510 | E58: 454 | F58: 2 | G58: 0 | H58: 1476 | I58: 0 | J58: 0 | K58: 0 | L58: 65334 | M58: 1244 | N58: 0 | O58: 0 | P58: 0 | Q58: 0
A59: 4J | B59: UMAE 10 HES 1 Mérida | C59: 3752 | D59: 12292 | E59: 8568 | F59: 991 | G59: 0 | H59: 0 | I59: 0 | J59: 0 | K59: 0 | L59: 0 | M59: 2733 | N59: 0 | O59: 0 | P59: 0 | Q59: 0
A60: 4K | B60: UMAE 11 HGO CMN La Raza | C60: 14804 | D60: 42067 | E60: 29389 | F60: 1401 | G60: 0 | H60: 2418 | I60: 8859 | J60: 0 | K60: 0 | L60: 0 | M60: 0 | N60: 0 | O60: 0 | P60: 0 | Q60: 0
A61: 4L | B61: UMAE 12 HGO San Angel | C61: 16093 | D61: 50111 | E61: 35467 | F61: 0 | G61: 0 | H61: 14644 | I61: 0 | J61: 0 | K61: 0 | L61: 0 | M61: 0 | N61: 0 | O61: 0 | P61: 0 | Q61: 0
...

Sheet Mortalidad
A7: =CONCATENATE("Mortalidad General por Grupos de Edad, ",Control!$B$3) -> Mortalidad General por Grupos de Edad, Preliminar Diciembre 2025
A8: Fuente: Subsistema Epidemiológico y Estadístico de Defunciones, SINBA - SEED
A10: Clave | B10: Nombre OOAD o UMAE | C10: Defunciones
C11: Total | D11: 0 | E11: 1 a 4 | F11: 5 a 9 | G11: 10 a 14 | H11: 15 a 19 | I11: 20 a 24 | J11: 25 a 29 | K11: 30 a 34 | L11: 35 a 39 | M11: 40 a 44 | N11: 45 a 49 | O11: 50 a 54 | P11: 55 a 59 | Q11: 60 a 64 | R11: 65 a 69 | S11: 70 a 74 | T11: 75 a 79 | U11: 80 a 85 | V11: 85 y más | W11: SD
A12: Nacional | C12: =+C13+C49+C76 -> 253132 | D12: =+D13+D49+D76 -> 3847 | E12: =+E13+E49+E76 -> 622 | F12: =+F13+F49+F76 -> 477 | G12: =+G13+G49+G76 -> 672 | H12: =+H13+H49+H76 -> 1155 | I12: =+I13+I49+I76 -> 1888 | J12: =+J13+J49+J76 -> 2685 | ... W12: =+W13+W49+W76 -> 2
A13: Total Delegaciones (Primer y Segundo Nivel) | C13: =+SUM(D13:W13) -> 133040 | D13: =+SUM(D14:D48) -> 2642 | E13: =+SUM(E14:E48) -> 300 | F13: =+SUM(F14:F48) -> 219 | G13: =+SUM(G14:G48) -> 272 | H13: =+SUM(H14:H48) -> 487 | I13: =+SUM(I14:I48) -> 788 | J13: =+SUM(J14:J48) -> 1246 | K13: =+SUM(K14:K48) -> 2095 | ... W13: =+SUM(W14:W48) -> 2
A14: 01 | B14: Aguascalientes | C14: 1997 | D14: 82 | E14: 4 | F14: 3 | G14: 6 | H14: 8 | I14: 16 | J14: 27 | K14: 52 | L14: 52 | M14: 55 | N14: 74 | O14: 123 | P14: 166 | Q14: 199 | R14: 250 | S14: 269 | T14: 238 | U14: 174 | V14: 199 | W14: 0
A15: 02 | B15: Baja California | C15: 6094 | D15: 93 | E15: 21 | F15: 11 | G15: 24 | H15: 34 | I15: 61 | J15: 75 | K15: 117 | L15: 161 | M15: 216 | N15: 305 | O15: 497 | P15: 626 | Q15: 761 | R15: 732 | S15: 679 | T15: 596 | U15: 535 | V15: 550 | W15: 0
A16: 03 | B16: Baja California Sur | C16: 1026 | D16: 37 | E16: 6 | F16: 4 | G16: 6 | H16: 5 | I16: 7 | J16: 6 | K16: 27 | L16: 29 | M16: 37 | N16: 56 | O16: 76 | P16: 63 | Q16: 127 | R16: 137 | S16: 109 | T16: 115 | U16: 92 | V16: 87 | W16: 0
A17: 04 | B17: Campeche | C17: 713 | D17: 20 | E17: 0 | F17: 1 | G17: 1 | H17: 1 | I17: 6 | J17: 10 | K17: 10 | L17: 11 | M17: 12 | N17: 34 | O17: 57 | P17: 72 | Q17: 68 | R17: 78 | S17: 113 | T17: 79 | U17: 65 | V17: 75 | W17: 0
A18: 05 | B18: Coahuila | C18: 6218 | D18: 214 | E18: 18 | F18: 14 | G18: 13 | H18: 23 | I18: 33 | J18: 53 | K18: 83 | L18: 93 | M18: 160 | N18: 307 | O18: 440 | P18: 585 | Q18: 799 | R18: 778 | S18: 714 | T18: 703 | U18: 571 | V18: 617 | W18: 0
A19: 06 | B19: Colima | C19: 1099 | D19: 12 | E19: 3 | F19: 4 | G19: 4 | H19: 2 | I19: 4 | J19: 10 | K19: 25 | L19: 20 | M19: 34 | N19: 30 | O19: 68 | P19: 96 | Q19: 116 | R19: 136 | S19: 137 | T19: 138 | U19: 119 | V19: 141 | W19: 0
A20: 07 | B20: Chiapas | C20: 1534 | D20: 39 | E20: 4 | F20: 3 | G20: 5 | H20: 12 | I20: 11 | J20: 21 | K20: 34 | L20: 42 | M20: 44 | N20: 68 | O20: 126 | P20: 160 | Q20: 190 | R20: 206 | S20: 190 | T20: 154 | U20: 114 | V20: 111 | W20: 0
A21: 08 | B21: Chihuahua | C21: 5705 | D21: 190 | E21: 19 | F21: 17 | G21: 11 | H21: 24 | I21: 23 | J21: 53 | K21: 85 | L21: 97 | M21: 186 | N21: 255 | O21: 423 | P21: 518 | Q21: 654 | R21: 766 | S21: 694 | T21: 649 | U21: 528 | V21: 513 | W21: 0
A22: 10 | B22: Durango | C22: 2744 | D22: 66 | E22: 11 | F22: 4 | G22: 6 | H22: 7 | I22: 17 | J22: 20 | K22: 31 | L22: 43 | M22: 53 | N22: 90 | O22: 175 | P22: 213 | Q22: 324 | R22: 357 | S22: 357 | T22: 356 | U22: 271 | V22: 343 | W22: 0
A23: 11 | B23: Guanajuato | C23: 4086 | D23: 52 | E23: 7 | F23: 8 | G23: 3 | H23: 9 | I23: 29 | J23: 49 | K23: 68 | L23: 93 | M23: 117 | N23: 190 | O23: 277 | P23: 387 | Q23: 481 | R23: 490 | S23: 531 | T23: 486 | U23: 393 | V23: 416 | W23: 0
A24: 12 | B24: Guerrero | C24: 1841 | D24: 36 | E24: 7 | F24: 4 | G24: 2 | H24: 10 | I24: 14 | J24: 18 | K24: 26 | L24: 28 | M24: 47 | N24: 86 | O24: 114 | P24: 148 | Q24: 233 | R24: 242 | S24: 244 | T24: 229 | U24: 154 | V24: 199 | W24: 0
A25: 13 | B25: Hidalgo | C25: 2167 | D25: 52 | E25: 6 | F25: 5 | G25: 8 | H25: 10 | I25: 18 | J25: 24 | K25: 37 | L25: 51 | M25: 57 | N25: 90 | O25: 156 | P25: 171 | Q25: 222 | R25: 269 | S25: 286 | T25: 238 | U25: 191 | V25: 276 | W25: 0
... A48: 40 | B48: Ciudad de México Sur | C48: 7513 | D48: 34 | E48: 2 | F48: 1 | G48: 4 | H48: 14 | I48: 23 | J48: 23 | K48: 57 | L48: 102 | M48: 138 | N48: 217 | O48: 361 | P48: 511 | Q48: 734 | R48: 934 | S48: 1046 | T48: 1062 | U48: 936 | V48: 1314 | W48: 0
A49: Total UMAE | C49: =+SUM(D49:W49) -> 11607 | D49: =+SUM(D50:D74) -> 1058 | E49: =+SUM(E50:E74) -> 186 | F49: =+SUM(F50:F74) -> 141 | G49: =+SUM(G50:G74) -> 170 | H49: =+SUM(H50:H74) -> 206 | I49: =+SUM(I50:I74) -> 178 | J49: =+SUM(J50:J74) -> 233 | K49: =+SUM(K50:K74) -> 327 | ... W49: =+SUM(W50:W74) -> 0
A50: 4A | B50: UMAE 01 HES CMN La Raza | C50: 989 | D50: 0 | E50: 0 | F50: 0 | G50: 0 | H50: 9 | I50: 22 | J50: 27 | K50: 40 | L50: 40 | M50: 55 | N50: 61 | O50: 89 | P50: 104 | Q50: 117 | R50: 136 | S50: 113 | T50: 83 | U50: 54 | V50: 39 | W50: 0
A51: 4B | B51: UMAE 02 HES CMN Siglo XXI | C51: 784 | D51: 0 | E51: 0 | F51: 0 | G51: 0 | H51: 7 | I51: 12 | J51: 14 | K51: 26 | L51: 31 | M51: 30 | N51: 47 | O51: 65 | P51: 75 | Q51: 110 | R51: 82 | S51: 106 | T51: 70 | U51: 54 | V51: 55 | W51: 0
A52: 4C | B52: UMAE 03 HES CMN Occidente | C52: 1368 | D52: 0 | E52: 0 | F52: 0 | G52: 0 | H52: 3 | I52: 31 | J52: 35 | K52: 54 | L52: 57 | M52: 54 | N52: 65 | O52: 115 | P52: 125 | Q52: 161 | R52: 166 | S52: 178 | T52: 151 | U52: 84 | V52: 89 | W52: 0
A53: 4D | B53: UMAE 04 HES Monterrey | C53: 1011 | D53: 18 | E53: 20 | F53: 16 | G53: 24 | H53: 20 | I53: 26 | J53: 30 | K53: 34 | L53: 41 | M53: 48 | N53: 75 | O53: 101 | P53: 134 | Q53: 128 | R53: 98 | S53: 82 | T53: 66 | U53: 34 | V53: 16 | W53: 0
A54: 4E | B54: UMAE 05 HES Torreón | C54: 682 | D54: 31 | E54: 9 | F54: 12 | G54: 14 | H54: 14 | I54: 14 | J54: 22 | K54: 17 | L54: 27 | M54: 39 | N54: 32 | O54: 54 | P54: 69 | Q54: 73 | R54: 85 | S54: 80 | T54: 59 | U54: 19 | V54: 12 | W54: 0
A55: 4F | B55: UMAE 06 HES Puebla | C55: 837 | D55: 1 | E55: 1 | F55: 3 | G55: 3 | H55: 13 | I55: 15 | J55: 20 | K55: 29 | L55: 27 | M55: 28 | N55: 58 | O55: 70 | P55: 85 | Q55: 114 | R55: 120 | S55: 110 | T55: 74 | U55: 36 | V55: 30 | W55: 0
A56: 4G | B56: UMAE 07 HES CMN del Bajío | C56: 685 | D56: 0 | E56: 0 | F56: 0 | G56: 0 | H56: 8 | I56: 11 | J56: 17 | K56: 20 | L56: 36 | M56: 22 | N56: 40 | O56: 53 | P56: 72 | Q56: 95 | R56: 102 | S56: 71 | T56: 67 | U56: 34 | V56: 37 | W56: 0
A57: 4H | B57: UMAE 08 HES Obregón | C57: 332 | D57: 0 | E57: 1 | F57: 0 | G57: 0 | H57: 3 | I57: 3 | J57: 5 | K57: 7 | L57: 18 | M57: 14 | N57: 17 | O57: 25 | P57: 29 | Q57: 34 | R57: 46 | S57: 48 | T57: 38 | U57: 28 | V57: 16 | W57: 0
A58: 4I | B58: UMAE 09 HES Veracruz | C58: 503 | D58: 10 | E58: 2 | F58: 3 | G58: 4 | H58: 6 | I58: 6 | J58: 8 | K58: 16 | L58: 14 | M58: 27 | N58: 22 | O58: 52 | P58: 54 | Q58: 57 | R58: 50 | S58: 49 | T58: 49 | U58: 34 | V58: 40 | W58: 0
A59: 4J | B59: UMAE 10 HES 1 Mérida | C59: 335 | D59: 40 | E59: 7 | F59: 2 | G59: 2 | H59: 8 | I59: 8 | J59: 12 | K59: 14 | L59: 7 | M59: 11 | N59: 25 | O59: 28 | P59: 22 | Q59: 32 | R59: 35 | S59: 41 | T59: 24 | U59: 10 | V59: 7 | W59: 0
A60: 4K | B60: UMAE 11 HGO CMN La Raza | C60: 274 | D60: 113 | E60: 0 | F60: 0 | G60: 0 | H60: 1 | I60: 2 | J60: 1 | K60: 4 | L60: 3 | M60: 12 | N60: 14 | O60: 26 | P60: 26 | Q60: 19 | R60: 22 | S60: 12 | T60: 10 | U60: 6 | V60: 3 | W60: 0
A61: 4L | B61: UMAE 12 HGO San Angel | C61: 100 | D61: 77 | E61: 0 | F61: 0 | G61: 0 | H61: 0 | I61: 0 | J61: 0 | K61: 0 | L61: 1 | M61: 2 | N61: 2 | O61: 2 | P61: 3 | Q61: 3 | R61: 3 | S61: 2 | T61: 2 | U61: 1 | V61: 2 | W61: 0
... A74: 4Y | B74: UMAE 25 HOnco CMN Siglo XXI | C74: 677 | D74: 0 | E74: 0 | F74: 0 | G74: 0 | H74: 2 | I74: 14 | J74: 9 | K74: 18 | L74: 20 | M74: 29 | N74: 37 | O74: 54 | P74: 88 | Q74: 108 | R74: 108 | S74: 85 | T74: 59 | U74: 35 | V74: 11 | W74: 0
A75: Certificadas fuera del IMSS | C75: =C76 -> 108485 | D75: =D76 -> 147 | E75: =E76 -> 136 | F75: =F76 -> 117 | G75: =G76 -> 230 | H75: =H76 -> 462 | I75: =I76 -> 922 | J75: =J76 -> 1206 | ... W75: =W76 -> 0
A76: 99 | B76: Fuera del IMSS | C76: 108485 | D76: 147 | E76: 136 | F76: 117 | G76: 230 | H76: 462 | I76: 922 | J76: 1206 | K76: 1455 | L76: 1772 | M76: 2165 | N76: 3168 | O76: 4661 | P76: 6129 | Q76: 8771 | R76: 11019 | S76: 12671 | T76: 13554 | U76: 14064 | V76: 25836 | W76: 0
